# SOME DESCRIPTIVE TITLE.
# Copyright (C) 2001-2021, Python Software Foundation
# This file is distributed under the same license as the Python package.
# FIRST AUTHOR <EMAIL@ADDRESS>, YEAR.
#
# Translators:
# tomo, 2020
#
#, fuzzy
msgid ""
msgstr ""
"Project-Id-Version: Python 3.8\n"
"Report-Msgid-Bugs-To: \n"
"POT-Creation-Date: 2021-01-01 16:06+0000\n"
"PO-Revision-Date: 2020-05-30 11:56+0000\n"
"Last-Translator: tomo, 2020\n"
"Language-Team: Japanese (https://www.transifex.com/python-doc/teams/5390/"
"ja/)\n"
"Language: ja\n"
"MIME-Version: 1.0\n"
"Content-Type: text/plain; charset=UTF-8\n"
"Content-Transfer-Encoding: 8bit\n"
"Plural-Forms: nplurals=1; plural=0;\n"

#: ../../library/asyncio-exceptions.rst:8
msgid "Exceptions"
msgstr "例外"

#: ../../library/asyncio-exceptions.rst:10
msgid "**Source code:** :source:`Lib/asyncio/exceptions.py`"
msgstr "**ソースコード:** :source:`Lib/asyncio/exceptions.py`"

#: ../../library/asyncio-exceptions.rst:16
msgid "The operation has exceeded the given deadline."
msgstr ""

#: ../../library/asyncio-exceptions.rst:19
msgid ""
"This exception is different from the builtin :exc:`TimeoutError` exception."
msgstr ""

#: ../../library/asyncio-exceptions.rst:25
msgid "The operation has been cancelled."
msgstr "処理がキャンセルされました。"

#: ../../library/asyncio-exceptions.rst:27
msgid ""
"This exception can be caught to perform custom operations when asyncio Tasks "
"are cancelled.  In almost all situations the exception must be re-raised."
msgstr ""
"asyncio タスクがキャンセルされた場合の処理をカスタマイズするために、この例外"
"を一旦キャッチすることができます。 ほとんどの場合、キャッチした例外は再度送出"
"しなければなりません。"

#: ../../library/asyncio-exceptions.rst:33
msgid ":exc:`CancelledError` is now a subclass of :class:`BaseException`."
msgstr ""
":exc:`CancelledError` は :class:`BaseException` の派生クラスになりました。"

#: ../../library/asyncio-exceptions.rst:38
msgid "Invalid internal state of :class:`Task` or :class:`Future`."
msgstr ":class:`Task` または :class:`Future` の内部状態が不正になりました。"

#: ../../library/asyncio-exceptions.rst:40
msgid ""
"Can be raised in situations like setting a result value for a *Future* "
"object that already has a result value set."
msgstr ""
"すでに結果の値が設定されている *Future* オブジェクトに対してさらに結果の値を"
"再び設定しようとする場合などに送出されることがあります。"

#: ../../library/asyncio-exceptions.rst:46
msgid ""
"The \"sendfile\" syscall is not available for the given socket or file type."
msgstr ""
"与えられたソケットまたはファイルタイプに対して \"sendfile\" システムコールが"
"利用可能ではありません。"

#: ../../library/asyncio-exceptions.rst:49
msgid "A subclass of :exc:`RuntimeError`."
msgstr ":exc:`RuntimeError` の派生クラスです。"

#: ../../library/asyncio-exceptions.rst:54
msgid "The requested read operation did not complete fully."
msgstr "要求された読み込み処理が完了できませんでした。"

#: ../../library/asyncio-exceptions.rst:56
msgid "Raised by the :ref:`asyncio stream APIs<asyncio-streams>`."
msgstr ":ref:`asyncio ストリーム API<asyncio-streams>` から送出されます。"

#: ../../library/asyncio-exceptions.rst:58
msgid "This exception is a subclass of :exc:`EOFError`."
msgstr "この例外は :exc:`EOFError` の派生クラスです。"

#: ../../library/asyncio-exceptions.rst:62
msgid "The total number (:class:`int`) of expected bytes."
msgstr "期待される総バイト数 (:class:`int`) です。"

#: ../../library/asyncio-exceptions.rst:66
msgid "A string of :class:`bytes` read before the end of stream was reached."
msgstr "ストリームの終端に達するまでに読み込んだ :class:`bytes` 文字列です。"

#: ../../library/asyncio-exceptions.rst:71
msgid "Reached the buffer size limit while looking for a separator."
msgstr "区切り文字を探している間にバッファサイズの上限に到達しました。"

#: ../../library/asyncio-exceptions.rst:73
msgid "Raised by the :ref:`asyncio stream APIs <asyncio-streams>`."
msgstr ":ref:`asyncio ストリーム API <asyncio-streams>` から送出されます。"

#: ../../library/asyncio-exceptions.rst:77
msgid "The total number of to be consumed bytes."
msgstr "未消費のバイトの合計数です。"
