# SOME DESCRIPTIVE TITLE.
# Copyright (C) 2001-2024, Python Software Foundation
# This file is distributed under the same license as the Python package.
# FIRST AUTHOR <EMAIL@ADDRESS>, YEAR.
#
# Translators:
# Arihiro TAKASE, 2023
# Masato HASHIMOTO <cabezon.hashimoto@gmail.com>, 2023
# Nozomu Kaneko <nozom.kaneko@gmail.com>, 2023
# tomo, 2023
# Takanori Suzuki <takanori@takanory.net>, 2024
#
#, fuzzy
msgid ""
msgstr ""
"Project-Id-Version: Python 3.13\n"
"Report-Msgid-Bugs-To: \n"
"POT-Creation-Date: 2024-10-04 14:17+0000\n"
"PO-Revision-Date: 2021-06-28 01:05+0000\n"
"Last-Translator: Takanori Suzuki <takanori@takanory.net>, 2024\n"
"Language-Team: Japanese (https://app.transifex.com/python-doc/teams/5390/"
"ja/)\n"
"MIME-Version: 1.0\n"
"Content-Type: text/plain; charset=UTF-8\n"
"Content-Transfer-Encoding: 8bit\n"
"Language: ja\n"
"Plural-Forms: nplurals=1; plural=0;\n"

#: ../../library/exceptions.rst:4
msgid "Built-in Exceptions"
msgstr "組み込み例外"

#: ../../library/exceptions.rst:10
msgid ""
"In Python, all exceptions must be instances of a class that derives from :"
"class:`BaseException`.  In a :keyword:`try` statement with an :keyword:"
"`except` clause that mentions a particular class, that clause also handles "
"any exception classes derived from that class (but not exception classes "
"from which *it* is derived).  Two exception classes that are not related via "
"subclassing are never equivalent, even if they have the same name."
msgstr ""
"Python において、すべての例外は :class:`BaseException` から派生したクラスのイ"
"ンスタンスでなければなりません。特定のクラスを言及する :keyword:`except` 節を"
"伴う :keyword:`try` 文において、その節はそのクラスから派生した例外クラスも処"
"理しますが、そのクラスの派生 *元* の例外クラスは処理しません。サブクラス化の"
"関係にない 2 つの例外クラスは、それらが同じ名前だった場合でも等しくなりえませ"
"ん。"

#: ../../library/exceptions.rst:19
msgid ""
"The built-in exceptions listed in this chapter can be generated by the "
"interpreter or built-in functions.  Except where mentioned, they have an "
"\"associated value\" indicating the detailed cause of the error.  This may "
"be a string or a tuple of several items of information (e.g., an error code "
"and a string explaining the code).  The associated value is usually passed "
"as arguments to the exception class's constructor."
msgstr ""
"この章で挙げる組み込み例外は、インタプリタや組み込み関数によって生成されま"
"す。特に注記しないかぎり、これらはエラーの詳しい原因を示す \"関連値 "
"(associated value)\" を持ちます。この値は、複数の情報 (エラーコードや、その"
"コードを説明する文字列など) の文字列かタプルです。関連値は通常、例外クラスの"
"コンストラクタに引数として渡されます。"

#: ../../library/exceptions.rst:26
msgid ""
"User code can raise built-in exceptions.  This can be used to test an "
"exception handler or to report an error condition \"just like\" the "
"situation in which the interpreter raises the same exception; but beware "
"that there is nothing to prevent user code from raising an inappropriate "
"error."
msgstr ""
"ユーザによるコードも組み込み例外を送出できます。これを使って、例外ハンドラを"
"テストしたり、インタプリタが同じ例外を送出する状況と \"ちょうど同じような\" "
"エラー条件であることを報告したりできます。しかし、ユーザのコードが適切でない"
"エラーを送出するのを妨げる方法はないので注意してください。"

#: ../../library/exceptions.rst:31
msgid ""
"The built-in exception classes can be subclassed to define new exceptions; "
"programmers are encouraged to derive new exceptions from the :exc:"
"`Exception` class or one of its subclasses, and not from :exc:"
"`BaseException`.  More information on defining exceptions is available in "
"the Python Tutorial under :ref:`tut-userexceptions`."
msgstr ""
"組み込み例外クラスは新たな例外を定義するためにサブクラス化することができま"
"す。新しい例外は、:exc:`Exception` クラスかそのサブクラスの一つから派生するこ"
"とをお勧めします。 :exc:`BaseException` からは派生しないで下さい。例外を定義"
"する上での詳しい情報は、 Python チュートリアルの :ref:`tut-userexceptions` の"
"項目にあります。"

#: ../../library/exceptions.rst:39
msgid "Exception context"
msgstr "例外コンテキスト"

#: ../../library/exceptions.rst:46
msgid ""
"Three attributes on exception objects provide information about the context "
"in which the exception was raised:"
msgstr ""
"例外オブジェクトの3つの属性は、例外が送出された常用に関する情報を提供します:"

#: ../../library/exceptions.rst:53
msgid ""
"When raising a new exception while another exception is already being "
"handled, the new exception's :attr:`!__context__` attribute is automatically "
"set to the handled exception.  An exception may be handled when an :keyword:"
"`except` or :keyword:`finally` clause, or a :keyword:`with` statement, is "
"used."
msgstr ""

#: ../../library/exceptions.rst:59
msgid ""
"This implicit exception context can be supplemented with an explicit cause "
"by using :keyword:`!from` with :keyword:`raise`::"
msgstr ""

#: ../../library/exceptions.rst:63
msgid "raise new_exc from original_exc"
msgstr ""

#: ../../library/exceptions.rst:65
msgid ""
"The expression following :keyword:`from<raise>` must be an exception or "
"``None``. It will be set as :attr:`!__cause__` on the raised exception. "
"Setting :attr:`!__cause__` also implicitly sets the :attr:`!"
"__suppress_context__` attribute to ``True``, so that using ``raise new_exc "
"from None`` effectively replaces the old exception with the new one for "
"display purposes (e.g. converting :exc:`KeyError` to :exc:`AttributeError`), "
"while leaving the old exception available in :attr:`!__context__` for "
"introspection when debugging."
msgstr ""
":keyword:`from <raise>` に続く式は例外か ``None`` でなくてはなりません。\n"
"式は送出される例外の :attr:`!__cause__` として設定されます。\n"
":attr:`!__cause__` を設定することは、 :attr:`!__suppress_context__` 属性を暗"
"黙的に ``True`` に設定することにもなるので、 ``raise new_exc from None`` を使"
"うことで効率的に古い例外を新しいもので置き換えて表示する (例えば、 :exc:"
"`KeyError` を :exc:`AttributeError` に置き換え)、古い例外はデバッグ時の調査で"
"使えるよう :attr:`!__context__` に残すことができます。"

#: ../../library/exceptions.rst:74
msgid ""
"The default traceback display code shows these chained exceptions in "
"addition to the traceback for the exception itself. An explicitly chained "
"exception in :attr:`!__cause__` is always shown when present. An implicitly "
"chained exception in :attr:`!__context__` is shown only if :attr:`!"
"__cause__` is :const:`None` and :attr:`!__suppress_context__` is false."
msgstr ""
"デフォルトの traceback 表示コードは、例外自体の traceback に加え、これらの連"
"鎖された例外を表示します。:attr:`!__cause__` で明示的に連鎖させた例外は、存在"
"するならば常に表示されます。:attr:`!__context__` で暗黙に連鎖させた例外は、:"
"attr:`!__cause__` が :const:`None` かつ :attr:`!__suppress_context__` が "
"false の場合にのみ表示されます。"

#: ../../library/exceptions.rst:80
msgid ""
"In either case, the exception itself is always shown after any chained "
"exceptions so that the final line of the traceback always shows the last "
"exception that was raised."
msgstr ""
"いずれにせよ、連鎖された例外に続いて、その例外自体は常に表示されます。そのた"
"め、traceback の最終行には、常に送出された最後の例外が表示されます。"

#: ../../library/exceptions.rst:86
msgid "Inheriting from built-in exceptions"
msgstr "組み込み例外から継承する"

#: ../../library/exceptions.rst:88
msgid ""
"User code can create subclasses that inherit from an exception type. It's "
"recommended to only subclass one exception type at a time to avoid any "
"possible conflicts between how the bases handle the ``args`` attribute, as "
"well as due to possible memory layout incompatibilities."
msgstr ""

#: ../../library/exceptions.rst:95
msgid ""
"Most built-in exceptions are implemented in C for efficiency, see: :source:"
"`Objects/exceptions.c`.  Some have custom memory layouts which makes it "
"impossible to create a subclass that inherits from multiple exception types. "
"The memory layout of a type is an implementation detail and might change "
"between Python versions, leading to new conflicts in the future.  Therefore, "
"it's recommended to avoid subclassing multiple exception types altogether."
msgstr ""

#: ../../library/exceptions.rst:105
msgid "Base classes"
msgstr "基底クラス"

#: ../../library/exceptions.rst:107
msgid ""
"The following exceptions are used mostly as base classes for other "
"exceptions."
msgstr "以下の例外は、主に他の例外の基底クラスとして使われます。"

#: ../../library/exceptions.rst:111
msgid ""
"The base class for all built-in exceptions.  It is not meant to be directly "
"inherited by user-defined classes (for that, use :exc:`Exception`).  If :"
"func:`str` is called on an instance of this class, the representation of the "
"argument(s) to the instance are returned, or the empty string when there "
"were no arguments."
msgstr ""
"全ての組み込み例外の基底クラスです。ユーザ定義の例外に直接継承されることは意"
"図されていません (継承には :exc:`Exception` を使ってください)。このクラスのイ"
"ンスタンスに :func:`str` が呼ばれた場合、インスタンスへの引数の表現か、引数が"
"無い場合には空文字列が返されます。"

#: ../../library/exceptions.rst:119
msgid ""
"The tuple of arguments given to the exception constructor.  Some built-in "
"exceptions (like :exc:`OSError`) expect a certain number of arguments and "
"assign a special meaning to the elements of this tuple, while others are "
"usually called only with a single string giving an error message."
msgstr ""
"例外コンストラクタに与えられた引数のタプルです。組み込み例外は普通、エラー"
"メッセージを与える一つの文字列だけを引数として呼ばれますが、中には (:exc:"
"`OSError` など) いくつかの引数を必要とし、このタプルの要素に特別な意味を込め"
"るものもあります。"

#: ../../library/exceptions.rst:126
msgid ""
"This method sets *tb* as the new traceback for the exception and returns the "
"exception object.  It was more commonly used before the exception chaining "
"features of :pep:`3134` became available.  The following example shows how "
"we can convert an instance of ``SomeException`` into an instance of "
"``OtherException`` while preserving the traceback.  Once raised, the current "
"frame is pushed onto the traceback of the ``OtherException``, as would have "
"happened to the traceback of the original ``SomeException`` had we allowed "
"it to propagate to the caller. ::"
msgstr ""

#: ../../library/exceptions.rst:135
msgid ""
"try:\n"
"    ...\n"
"except SomeException:\n"
"    tb = sys.exception().__traceback__\n"
"    raise OtherException(...).with_traceback(tb)"
msgstr ""

#: ../../library/exceptions.rst:143
msgid ""
"A writable field that holds the :ref:`traceback object <traceback-objects>` "
"associated with this exception. See also: :ref:`raise`."
msgstr ""

#: ../../library/exceptions.rst:149
msgid ""
"Add the string ``note`` to the exception's notes which appear in the "
"standard traceback after the exception string. A :exc:`TypeError` is raised "
"if ``note`` is not a string."
msgstr ""
"例外のノートとして文字列 ``note`` を追加します。ノートは標準のトレースバック"
"で例外文字列の後に表示されます。``note`` が文字列以外の場合 :exc:`TypeError` "
"が送出されます。"

#: ../../library/exceptions.rst:157
msgid ""
"A list of the notes of this exception, which were added with :meth:"
"`add_note`. This attribute is created when :meth:`add_note` is called."
msgstr ""
":meth:`add_note` で追加された例外のノートのリスト。この属性は :meth:"
"`add_note` を呼び出すと生成されます。"

#: ../../library/exceptions.rst:165
msgid ""
"All built-in, non-system-exiting exceptions are derived from this class.  "
"All user-defined exceptions should also be derived from this class."
msgstr ""
"システム終了以外の全ての組み込み例外はこのクラスから派生しています。全ての"
"ユーザ定義例外もこのクラスから派生させるべきです。"

#: ../../library/exceptions.rst:171
msgid ""
"The base class for those built-in exceptions that are raised for various "
"arithmetic errors: :exc:`OverflowError`, :exc:`ZeroDivisionError`, :exc:"
"`FloatingPointError`."
msgstr ""
"算術上の様々なエラーに対して送出される組み込み例外 :exc:`OverflowError`, :"
"exc:`ZeroDivisionError`, :exc:`FloatingPointError` の基底クラスです。"

#: ../../library/exceptions.rst:178
msgid ""
"Raised when a :ref:`buffer <bufferobjects>` related operation cannot be "
"performed."
msgstr ""
":ref:`バッファ <bufferobjects>` に関連する操作が行えなかったときに送出されま"
"す。"

#: ../../library/exceptions.rst:184
msgid ""
"The base class for the exceptions that are raised when a key or index used "
"on a mapping or sequence is invalid: :exc:`IndexError`, :exc:`KeyError`.  "
"This can be raised directly by :func:`codecs.lookup`."
msgstr ""
"マッピングまたはシーケンスで使われたキーやインデクスが無効な場合に送出される"
"例外 :exc:`IndexError` および :exc:`KeyError` の基底クラスです。 :func:"
"`codecs.lookup` によって直接送出されることもあります。"

#: ../../library/exceptions.rst:190
msgid "Concrete exceptions"
msgstr "具象例外"

#: ../../library/exceptions.rst:192
msgid "The following exceptions are the exceptions that are usually raised."
msgstr "以下の例外は、通常送出される例外です。"

#: ../../library/exceptions.rst:198
msgid "Raised when an :keyword:`assert` statement fails."
msgstr ":keyword:`assert` 文が失敗した場合に送出されます。"

#: ../../library/exceptions.rst:203
msgid ""
"Raised when an attribute reference (see :ref:`attribute-references`) or "
"assignment fails.  (When an object does not support attribute references or "
"attribute assignments at all, :exc:`TypeError` is raised.)"
msgstr ""
"属性参照 (:ref:`attribute-references` を参照) や代入が失敗した場合に送出され"
"ます (オブジェクトが属性の参照や属性の代入をまったくサポートしていない場合に"
"は :exc:`TypeError` が送出されます)。"

#: ../../library/exceptions.rst:207
msgid ""
"The :attr:`name` and :attr:`obj` attributes can be set using keyword-only "
"arguments to the constructor. When set they represent the name of the "
"attribute that was attempted to be accessed and the object that was accessed "
"for said attribute, respectively."
msgstr ""
"コンストラクタのキーワード専用引数を使って :attr:`name` および :attr:`obj` 属"
"性を設定できます。設定された場合、アクセスが試みられた属性の名前と、その属性"
"にアクセスしたオブジェクトを、それぞれ表します。"

#: ../../library/exceptions.rst:212
msgid "Added the :attr:`name` and :attr:`obj` attributes."
msgstr ":attr:`name` および :attr:`obj` 属性が追加されました。"

#: ../../library/exceptions.rst:217
msgid ""
"Raised when the :func:`input` function hits an end-of-file condition (EOF) "
"without reading any data. (N.B.: the :meth:`io.IOBase.read` and :meth:`io."
"IOBase.readline` methods return an empty string when they hit EOF.)"
msgstr ""
":func:`input` が何もデータを読まずに end-of-file (EOF) に達した場合に送出され"
"ます。(注意:  :meth:`io.IOBase.read` と :meth:`io.IOBase.readline` メソッド"
"は、EOF に達すると空文字列を返します。)"

#: ../../library/exceptions.rst:224
msgid "Not currently used."
msgstr "現在は使われていません。"

#: ../../library/exceptions.rst:229
msgid ""
"Raised when a :term:`generator` or :term:`coroutine` is closed; see :meth:"
"`generator.close` and :meth:`coroutine.close`.  It directly inherits from :"
"exc:`BaseException` instead of :exc:`Exception` since it is technically not "
"an error."
msgstr ""
":term:`ジェネレータ <generator>` や :term:`コルーチン <coroutine>` が閉じられ"
"たときに送出されます。 :meth:`generator.close` と :meth:`coroutine.close` を"
"参照してください。この例外は厳密に言えばエラーではないので、 :exc:"
"`Exception` ではなく :exc:`BaseException` を直接継承しています。"

#: ../../library/exceptions.rst:237
msgid ""
"Raised when the :keyword:`import` statement has troubles trying to load a "
"module.  Also raised when the \"from list\" in ``from ... import`` has a "
"name that cannot be found."
msgstr ""
":keyword:`import` 文でモジュールをロードしようとして問題が発生すると送出され"
"ます。\n"
"``from ... import`` の中の\"from list\" (訳注：``...`` の部分)の名前が見つか"
"らないときにも送出されます。"

#: ../../library/exceptions.rst:241
msgid ""
"The optional *name* and *path* keyword-only arguments set the corresponding "
"attributes:"
msgstr ""
"オブションのキーワード専用引数  *name* と *path* は、対応する属性に設定されま"
"す:"

#: ../../library/exceptions.rst:246
msgid "The name of the module that was attempted to be imported."
msgstr "インポートを試みたモジュールの名前。"

#: ../../library/exceptions.rst:250
msgid "The path to any file which triggered the exception."
msgstr "例外を引き起こしたファイルのパス。"

#: ../../library/exceptions.rst:252
msgid "Added the :attr:`name` and :attr:`path` attributes."
msgstr ":attr:`name` および :attr:`path` 属性が追加されました。"

#: ../../library/exceptions.rst:257
msgid ""
"A subclass of :exc:`ImportError` which is raised by :keyword:`import` when a "
"module could not be located.  It is also raised when ``None`` is found in :"
"data:`sys.modules`."
msgstr ""
":exc:`ImportError` のサブクラスで、:keyword:`import` 文でモジュールが見つから"
"ない場合に送出されます。また、 :data:`sys.modules` に ``None`` が含まれる場合"
"にも送出されます。"

#: ../../library/exceptions.rst:266
msgid ""
"Raised when a sequence subscript is out of range.  (Slice indices are "
"silently truncated to fall in the allowed range; if an index is not an "
"integer, :exc:`TypeError` is raised.)"
msgstr ""
"シーケンスの添字が範囲外の場合に送出されます。 (スライスのインデクスはシーケ"
"ンスの範囲に収まるように暗黙のうちに調整されます; インデクスが整数でない場"
"合、 :exc:`TypeError` が送出されます。)"

#: ../../library/exceptions.rst:275
msgid ""
"Raised when a mapping (dictionary) key is not found in the set of existing "
"keys."
msgstr ""
"マッピング (辞書) のキーが、既存のキーの集合内に見つからなかった場合に送出さ"
"れます。"

#: ../../library/exceptions.rst:282
msgid ""
"Raised when the user hits the interrupt key (normally :kbd:`Control-C` or :"
"kbd:`Delete`).  During execution, a check for interrupts is made regularly. "
"The exception inherits from :exc:`BaseException` so as to not be "
"accidentally caught by code that catches :exc:`Exception` and thus prevent "
"the interpreter from exiting."
msgstr ""
"ユーザが割り込みキー (通常は :kbd:`Control-C` または :kbd:`Delete`) を押した"
"場合に送出されます。実行中、割り込みは定期的に監視されます。:exc:`Exception` "
"を捕捉するコードに誤って捕捉されてインタプリタの終了が阻害されないように、こ"
"の例外は :exc:`BaseException` を継承しています。"

#: ../../library/exceptions.rst:290
msgid ""
"Catching a :exc:`KeyboardInterrupt` requires special consideration. Because "
"it can be raised at unpredictable points, it may, in some circumstances, "
"leave the running program in an inconsistent state. It is generally best to "
"allow :exc:`KeyboardInterrupt` to end the program as quickly as possible or "
"avoid raising it entirely. (See :ref:`handlers-and-exceptions`.)"
msgstr ""

#: ../../library/exceptions.rst:300
msgid ""
"Raised when an operation runs out of memory but the situation may still be "
"rescued (by deleting some objects).  The associated value is a string "
"indicating what kind of (internal) operation ran out of memory. Note that "
"because of the underlying memory management architecture (C's :c:func:"
"`malloc` function), the interpreter may not always be able to completely "
"recover from this situation; it nevertheless raises an exception so that a "
"stack traceback can be printed, in case a run-away program was the cause."
msgstr ""
"ある操作中にメモリが不足したが、その状況は (オブジェクトをいくつか消去するこ"
"とで) まだ復旧可能かもしれない場合に送出されます。この例外の関連値は、メモリ"
"不足になった (内部) 操作の種類を示す文字列です。下層のメモリ管理アーキテク"
"チャ (C の :c:func:`malloc` 関数) のために、インタプリタが現状から完璧に復旧"
"できるとはかぎらないので注意してください。それでも、プログラムの暴走が原因の"
"場合に備えて実行スタックのトレースバックを出力できるように、例外が送出されま"
"す。"

#: ../../library/exceptions.rst:311
msgid ""
"Raised when a local or global name is not found.  This applies only to "
"unqualified names.  The associated value is an error message that includes "
"the name that could not be found."
msgstr ""
"ローカルまたはグローバルの名前が見つからなかった場合に送出されます。これは非"
"修飾の (訳注: ``spam.egg`` ではなく単に ``egg`` のような) 名前のみに適用され"
"ます。関連値は見つからなかった名前を含むエラーメッセージです。"

#: ../../library/exceptions.rst:315
msgid ""
"The :attr:`name` attribute can be set using a keyword-only argument to the "
"constructor. When set it represent the name of the variable that was "
"attempted to be accessed."
msgstr ""
"コンストラクタのキーワード専用引数を使って :attr:`name` 属性を設定できます。"
"設定された場合、アクセスが試みられた変数の名前を表します。"

#: ../../library/exceptions.rst:319
msgid "Added the :attr:`name` attribute."
msgstr ":attr:`name` 属性が追加されました。"

#: ../../library/exceptions.rst:325
msgid ""
"This exception is derived from :exc:`RuntimeError`.  In user defined base "
"classes, abstract methods should raise this exception when they require "
"derived classes to override the method, or while the class is being "
"developed to indicate that the real implementation still needs to be added."
msgstr ""
"この例外は :exc:`RuntimeError` から派生しています。ユーザ定義の基底クラスにお"
"いて、抽象メソッドが派生クラスでオーバライドされることを要求する場合にこの例"
"外を送出しなくてはなりません。またはクラスは実装中であり本来の実装を追加する"
"必要があることを示します。"

#: ../../library/exceptions.rst:332
msgid ""
"It should not be used to indicate that an operator or method is not meant to "
"be supported at all -- in that case either leave the operator / method "
"undefined or, if a subclass, set it to :data:`None`."
msgstr ""
"演算子やメソッドがサポートされていないことを示す目的でこの例外を使用するべき"
"ではありません。そのようなケースではオペレータやメソッドを未定義のままとする"
"か、サブクラスの場合は :data:`None` を設定してください。"

#: ../../library/exceptions.rst:338
msgid ""
"``NotImplementedError`` and :data:`NotImplemented` are not interchangeable, "
"even though they have similar names and purposes.  See :data:`!"
"NotImplemented` for details on when to use it."
msgstr ""
"``NotImplementedError`` と :data:`NotImplemented` は、似たような名前と目的を"
"持っていますが、相互に変換できません。 利用する際には、:data:`!"
"NotImplemented` を参照してください。"

#: ../../library/exceptions.rst:347
msgid ""
"This exception is raised when a system function returns a system-related "
"error, including I/O failures such as \"file not found\" or \"disk "
"full\" (not for illegal argument types or other incidental errors)."
msgstr ""
"この例外はシステム関数がシステム関連のエラーを返した場合に送出されます。例え"
"ば \"file not found\" や \"disk full\" のような I/O の失敗が発生したときです "
"(引数の型が不正な場合や、他の偶発的なエラーは除きます)。"

#: ../../library/exceptions.rst:351
msgid ""
"The second form of the constructor sets the corresponding attributes, "
"described below.  The attributes default to :const:`None` if not specified.  "
"For backwards compatibility, if three arguments are passed, the :attr:"
"`~BaseException.args` attribute contains only a 2-tuple of the first two "
"constructor arguments."
msgstr ""
"コンストラクタの2番目の形式は下記の対応する属性を設定します。指定されなかった"
"場合属性はデフォルトで :const:`None` です。後方互換性のために、引数が3つ渡さ"
"れた場合、:attr:`~BaseException.args` 属性は最初の2つの要素のみからなるタプル"
"を持ちます。"

#: ../../library/exceptions.rst:357
msgid ""
"The constructor often actually returns a subclass of :exc:`OSError`, as "
"described in `OS exceptions`_ below.  The particular subclass depends on the "
"final :attr:`.errno` value.  This behaviour only occurs when constructing :"
"exc:`OSError` directly or via an alias, and is not inherited when "
"subclassing."
msgstr ""
"コンストラクタは実際には、 `OS exceptions`_ で述べられている :exc:`OSError` "
"のサブクラスを返すことがよくあります。特定のサブクラスは最終的な :attr:`."
"errno` 値によります。この挙動は :exc:`OSError` を直接またはエイリアスで構築"
"し、サブクラス化時に継承されなかった場合にのみ発生します。"

#: ../../library/exceptions.rst:365
msgid "A numeric error code from the C variable :c:data:`errno`."
msgstr "C 変数 :c:data:`errno` に由来する数値エラーコードです。"

#: ../../library/exceptions.rst:369
msgid ""
"Under Windows, this gives you the native Windows error code.  The :attr:`."
"errno` attribute is then an approximate translation, in POSIX terms, of that "
"native error code."
msgstr ""
"Windows において、ネイティブ Windows エラーコードを与えます。そして :attr:"
"`errno` 属性は POSIX でいうネイティブエラーコードへのおよその翻訳です。"

#: ../../library/exceptions.rst:373
msgid ""
"Under Windows, if the *winerror* constructor argument is an integer, the :"
"attr:`.errno` attribute is determined from the Windows error code, and the "
"*errno* argument is ignored.  On other platforms, the *winerror* argument is "
"ignored, and the :attr:`winerror` attribute does not exist."
msgstr ""
"Windows では、*winerror* コンストラクタ引数が整数の場合 :attr:`.errno` 属性"
"は Windows エラーコードから決定され、*errno* 引数は無視されます。他のプラット"
"フォームでは *winerror* 引数は無視され、 :attr:`winerror` 属性は存在しませ"
"ん。"

#: ../../library/exceptions.rst:381
msgid ""
"The corresponding error message, as provided by the operating system.  It is "
"formatted by the C functions :c:func:`perror` under POSIX, and :c:func:"
"`FormatMessage` under Windows."
msgstr ""
"OS が提供するような、対応するエラーメッセージです。\n"
"POSIX では :c:func:`perror` で、Windows では :c:func:`FormatMessage` で体裁化"
"されます。"

#: ../../library/exceptions.rst:389
msgid ""
"For exceptions that involve a file system path (such as :func:`open` or :"
"func:`os.unlink`), :attr:`filename` is the file name passed to the function. "
"For functions that involve two file system paths (such as :func:`os."
"rename`), :attr:`filename2` corresponds to the second file name passed to "
"the function."
msgstr ""
"ファイルシステムパスが1つ関与する例外 (例えば :func:`open` や :func:`os."
"unlink`) の場合、:attr:`filename` は関数に渡されたファイル名です。\n"
"ファイルシステムパスが2つ関与する関数 (例えば :func:`os.rename`) の場合、:"
"attr:`filename2` は関数に渡された2つ目のファイル名です。"

#: ../../library/exceptions.rst:396
msgid ""
":exc:`EnvironmentError`, :exc:`IOError`, :exc:`WindowsError`, :exc:`socket."
"error`, :exc:`select.error` and :exc:`mmap.error` have been merged into :exc:"
"`OSError`, and the constructor may return a subclass."
msgstr ""
":exc:`EnvironmentError`, :exc:`IOError`, :exc:`WindowsError`, :exc:`socket."
"error`, :exc:`select.error`, :exc:`mmap.error` が :exc:`OSError` に統合されま"
"した。コンストラクタはサブクラスを返すかもしれません。"

#: ../../library/exceptions.rst:402
msgid ""
"The :attr:`filename` attribute is now the original file name passed to the "
"function, instead of the name encoded to or decoded from the :term:"
"`filesystem encoding and error handler`. Also, the *filename2* constructor "
"argument and attribute was added."
msgstr ""
":attr:`filename` 属性が :term:`filesystem encoding and error handler` のエン"
"コーディングでエンコードやデコードされた名前から、関数に渡された元々のファイ"
"ル名になりました。\n"
"また、*filename2* コンストラクタ引数が追加されました。"

#: ../../library/exceptions.rst:411
msgid ""
"Raised when the result of an arithmetic operation is too large to be "
"represented.  This cannot occur for integers (which would rather raise :exc:"
"`MemoryError` than give up).  However, for historical reasons, OverflowError "
"is sometimes raised for integers that are outside a required range.   "
"Because of the lack of standardization of floating-point exception handling "
"in C, most floating-point operations are not checked."
msgstr ""
"算術演算の結果が表現できない大きな値になった場合に送出されます。これは整数で"
"は起こりません (むしろ :exc:`MemoryError` が送出されることになるでしょう)。し"
"かし、歴史的な理由のため、要求された範囲の外の整数に対して OverflowError が送"
"出されることがあります。C の浮動小数点演算の例外処理は標準化されていないの"
"で、ほとんどの浮動小数点演算もチェックされません。"

#: ../../library/exceptions.rst:421
msgid ""
"This exception is derived from :exc:`RuntimeError`.  It is raised when an "
"operation is blocked during interpreter shutdown also known as :term:`Python "
"finalization <interpreter shutdown>`."
msgstr ""

#: ../../library/exceptions.rst:425
msgid ""
"Examples of operations which can be blocked with a :exc:"
"`PythonFinalizationError` during the Python finalization:"
msgstr ""

#: ../../library/exceptions.rst:428
msgid "Creating a new Python thread."
msgstr ""

#: ../../library/exceptions.rst:429
msgid ":func:`os.fork`."
msgstr ":func:`os.fork`"

#: ../../library/exceptions.rst:431
msgid "See also the :func:`sys.is_finalizing` function."
msgstr ":func:`sys.is_finalizing` 関数も参照してください。"

#: ../../library/exceptions.rst:433 ../../library/exceptions.rst:443
msgid "Previously, a plain :exc:`RuntimeError` was raised."
msgstr "以前は :exc:`RuntimeError` をそのまま送出していました。"

#: ../../library/exceptions.rst:439
msgid ""
"This exception is derived from :exc:`RuntimeError`.  It is raised when the "
"interpreter detects that the maximum recursion depth (see :func:`sys."
"getrecursionlimit`) is exceeded."
msgstr ""
"この例外は :exc:`RuntimeError` を継承しています。インタープリタが最大再帰深"
"度 (:func:`sys.getrecursionlimit` を参照) の超過を検出すると送出されます。"

#: ../../library/exceptions.rst:449
msgid ""
"This exception is raised when a weak reference proxy, created by the :func:"
"`weakref.proxy` function, is used to access an attribute of the referent "
"after it has been garbage collected. For more information on weak "
"references, see the :mod:`weakref` module."
msgstr ""
":func:`weakref.proxy` によって生成された弱参照 (weak reference) プロキシを"
"使って、ガーベジコレクションによって回収された後の参照対象オブジェクトの属性"
"にアクセスした場合に送出されます。弱参照については :mod:`weakref` モジュール"
"を参照してください。"

#: ../../library/exceptions.rst:457
msgid ""
"Raised when an error is detected that doesn't fall in any of the other "
"categories.  The associated value is a string indicating what precisely went "
"wrong."
msgstr ""
"他のカテゴリに分類できないエラーが検出された場合に送出されます。関連値は、何"
"が問題だったのかをより詳細に示す文字列です。"

#: ../../library/exceptions.rst:464
msgid ""
"Raised by built-in function :func:`next` and an :term:`iterator`\\'s :meth:"
"`~iterator.__next__` method to signal that there are no further items "
"produced by the iterator."
msgstr ""
"組込み関数 :func:`next` と :term:`iterator` の :meth:`~iterator.__next__` メ"
"ソッドによって、そのイテレータが生成するアイテムがこれ以上ないことを伝えるた"
"めに送出されます。"

#: ../../library/exceptions.rst:470
msgid ""
"The exception object has a single attribute :attr:`!value`, which is given "
"as an argument when constructing the exception, and defaults to :const:"
"`None`."
msgstr ""
"この例外オブジェクトには一つの属性 :attr:`!value` があり、例外を構成する際に"
"引数として与えられ、デフォルトは :const:`None` です。"

#: ../../library/exceptions.rst:474
msgid ""
"When a :term:`generator` or :term:`coroutine` function returns, a new :exc:"
"`StopIteration` instance is raised, and the value returned by the function "
"is used as the :attr:`value` parameter to the constructor of the exception."
msgstr ""
":term:`generator` や :term:`coroutine` 関数が返るとき、新しい :exc:"
"`StopIteration` インスタンスが送出されます。\n"
"関数の返り値は例外のコンストラクタの :attr:`value` 引数として使われます。"

#: ../../library/exceptions.rst:479
msgid ""
"If a generator code directly or indirectly raises :exc:`StopIteration`, it "
"is converted into a :exc:`RuntimeError` (retaining the :exc:`StopIteration` "
"as the new exception's cause)."
msgstr ""
"ジェネレータのコードが直接的あるいは間接的に :exc:`StopIteration` を送出する"
"場合は、 :exc:`RuntimeError` に変換されます (:exc:`StopIteration` は変換後の"
"例外の原因として保持されます)。"

#: ../../library/exceptions.rst:483
msgid ""
"Added ``value`` attribute and the ability for generator functions to use it "
"to return a value."
msgstr ""
"``value`` 属性とジェネレータ関数が値を返すためにそれを使う機能が追加されまし"
"た。"

#: ../../library/exceptions.rst:487
msgid ""
"Introduced the RuntimeError transformation via ``from __future__ import "
"generator_stop``, see :pep:`479`."
msgstr ""
"``from __future__ import generator_stop`` による RuntimeError への変換が導入"
"されました。 :pep:`479` を参照してください。"

#: ../../library/exceptions.rst:491
msgid ""
"Enable :pep:`479` for all code by default: a :exc:`StopIteration` error "
"raised in a generator is transformed into a :exc:`RuntimeError`."
msgstr ""
":pep:`479` が全てのコードでデフォルトで有効化されました: ジェネレータから送出"
"された :exc:`StopIteration` は :exc:`RuntimeError` に変換されます。"

#: ../../library/exceptions.rst:497
msgid ""
"Must be raised by :meth:`~object.__anext__` method of an :term:`asynchronous "
"iterator` object to stop the iteration."
msgstr ""
"イテレーションを停止するために、 :term:`asynchronous iterator` オブジェクト"
"の :meth:`~object.__anext__` メソッドによって返される必要があります。"

#: ../../library/exceptions.rst:504
msgid ""
"Raised when the parser encounters a syntax error.  This may occur in an :"
"keyword:`import` statement, in a call to the built-in functions :func:"
"`compile`, :func:`exec`, or :func:`eval`, or when reading the initial script "
"or standard input (also interactively)."
msgstr ""
"パーザが構文エラーに遭遇した場合に送出されます。この例外は :keyword:`import` "
"文、組み込み関数 :func:`compile`、:func:`exec` や :func:`eval` 、初期化スクリ"
"プトの読み込みや標準入力で (対話的な実行時にも) 起こる可能性があります。"

#: ../../library/exceptions.rst:510
msgid ""
"The :func:`str` of the exception instance returns only the error message. "
"Details is a tuple whose members are also available as separate attributes."
msgstr ""
"例外インスタンスの :func:`str` はエラーメッセージのみを返します。詳細はタプル"
"で、個々の属性としても利用できます。"

#: ../../library/exceptions.rst:515
msgid "The name of the file the syntax error occurred in."
msgstr "構文エラーが発生したファイルの名前。"

#: ../../library/exceptions.rst:519
msgid ""
"Which line number in the file the error occurred in. This is 1-indexed: the "
"first line in the file has a ``lineno`` of 1."
msgstr ""
"ファイルのエラーが発生した行番号。1から数えはじめるため、ファイルの最初の行"
"の ``lineno`` は1です。"

#: ../../library/exceptions.rst:524
msgid ""
"The column in the line where the error occurred. This is 1-indexed: the "
"first character in the line has an ``offset`` of 1."
msgstr ""
"行のエラーが発生した列番号。1から数えはじめるため、行の最初の文字の "
"``offset`` は1です。"

#: ../../library/exceptions.rst:529
msgid "The source code text involved in the error."
msgstr "エラーを含むソースコードのテキスト。"

#: ../../library/exceptions.rst:533
msgid ""
"Which line number in the file the error occurred ends in. This is 1-indexed: "
"the first line in the file has a ``lineno`` of 1."
msgstr ""
"ファイルのエラーが発生した最後の行番号。1から数えはじめるため、ファイルの最初"
"の行の ``lineno`` は1です。"

#: ../../library/exceptions.rst:538
msgid ""
"The column in the end line where the error occurred finishes. This is 1-"
"indexed: the first character in the line has an ``offset`` of 1."
msgstr ""
"行のエラーが発生した最後の列番号。1から数えはじめるため、行の最初の文字の "
"``offset`` は1です。"

#: ../../library/exceptions.rst:541
msgid ""
"For errors in f-string fields, the message is prefixed by \"f-string: \" and "
"the offsets are offsets in a text constructed from the replacement "
"expression.  For example, compiling f'Bad {a b} field' results in this args "
"attribute: ('f-string: ...', ('', 1, 2, '(a b)\\n', 1, 5))."
msgstr ""

#: ../../library/exceptions.rst:546
msgid "Added the :attr:`end_lineno` and :attr:`end_offset` attributes."
msgstr ":attr:`end_lineno` および :attr:`end_offset` 属性が追加されました。"

#: ../../library/exceptions.rst:551
msgid ""
"Base class for syntax errors related to incorrect indentation.  This is a "
"subclass of :exc:`SyntaxError`."
msgstr ""
"正しくないインデントに関する構文エラーの基底クラスです。これは :exc:"
"`SyntaxError` のサブクラスです。"

#: ../../library/exceptions.rst:557
msgid ""
"Raised when indentation contains an inconsistent use of tabs and spaces. "
"This is a subclass of :exc:`IndentationError`."
msgstr ""
"タブとスペースを一貫しない方法でインデントに使っているときに送出されます。こ"
"れは :exc:`IndentationError` のサブクラスです。"

#: ../../library/exceptions.rst:563
msgid ""
"Raised when the interpreter finds an internal error, but the situation does "
"not look so serious to cause it to abandon all hope. The associated value is "
"a string indicating what went wrong (in low-level terms)."
msgstr ""
"インタプリタが内部エラーを発見したが、状況は全ての望みを棄てさせるほど深刻で"
"はないと思われる場合に送出されます。関連値は (下位層で) どの動作が失敗したか"
"を示す文字列です。"

#: ../../library/exceptions.rst:567
msgid ""
"You should report this to the author or maintainer of your Python "
"interpreter. Be sure to report the version of the Python interpreter (``sys."
"version``; it is also printed at the start of an interactive Python "
"session), the exact error message (the exception's associated value) and if "
"possible the source of the program that triggered the error."
msgstr ""
"使用中の Python インタプリタの作者または保守担当者にこのエラーを報告してくだ"
"さい。このとき、Python インタプリタのバージョン (``sys.version`` 。Python の"
"対話的セッションを開始した際にも出力されます)、正確なエラーメッセージ (例外の"
"関連値) を忘れずに報告してください。可能な場合にはエラーを引き起こしたプログ"
"ラムのソースコードも報告してください。"

#: ../../library/exceptions.rst:576
msgid ""
"This exception is raised by the :func:`sys.exit` function.  It inherits "
"from :exc:`BaseException` instead of :exc:`Exception` so that it is not "
"accidentally caught by code that catches :exc:`Exception`.  This allows the "
"exception to properly propagate up and cause the interpreter to exit.  When "
"it is not handled, the Python interpreter exits; no stack traceback is "
"printed.  The constructor accepts the same optional argument passed to :func:"
"`sys.exit`. If the value is an integer, it specifies the system exit status "
"(passed to C's :c:func:`exit` function); if it is ``None``, the exit status "
"is zero; if it has another type (such as a string), the object's value is "
"printed and the exit status is one."
msgstr ""
"この例外は :func:`sys.exit` 関数から送出されます。:exc:`Exception` をキャッチ"
"するコードに誤ってキャッチされないように、:exc:`Exception` ではなく :exc:"
"`BaseException` を継承しています。これにより例外は上の階層に適切に伝わり、イ"
"ンタープリタを終了させます。この例外が処理されなかった場合はスタックのトレー"
"スバックを表示せずに Python インタープリタは終了します。コンストラクタは :"
"func:`sys.exit` に渡されるオプション引数と同じものを受け取ります。値が整数の"
"場合、システムの終了ステータス (C 言語の :c:func:`exit` 関数に渡すもの)を指定"
"します。値が ``None`` の場合、終了ステータスは 0 です。それ以外の型の場合 (例"
"えば str)、 オブジェクトの値が表示され、終了ステータスは 1 です。"

#: ../../library/exceptions.rst:587
msgid ""
"A call to :func:`sys.exit` is translated into an exception so that clean-up "
"handlers (:keyword:`finally` clauses of :keyword:`try` statements) can be "
"executed, and so that a debugger can execute a script without running the "
"risk of losing control.  The :func:`os._exit` function can be used if it is "
"absolutely positively necessary to exit immediately (for example, in the "
"child process after a call to :func:`os.fork`)."
msgstr ""
":func:`sys.exit` は、クリーンアップのための処理 (:keyword:`try` 文の :"
"keyword:`finally` 節) が実行されるようにするため、またデバッガが制御不能にな"
"るリスクを冒さずにスクリプトを実行できるようにするために例外に変換されます。"
"即座に終了することが真に強く必要であるとき (例えば、:func:`os.fork` を呼んだ"
"後の子プロセス内) には :func:`os._exit` 関数を使うことができます。"

#: ../../library/exceptions.rst:596
msgid ""
"The exit status or error message that is passed to the constructor. "
"(Defaults to ``None``.)"
msgstr ""
"コンストラクタに渡された終了ステータス又はエラーメッセージ。(デフォルトは "
"``None``)"

#: ../../library/exceptions.rst:602
msgid ""
"Raised when an operation or function is applied to an object of "
"inappropriate type.  The associated value is a string giving details about "
"the type mismatch."
msgstr ""
"組み込み演算または関数が適切でない型のオブジェクトに対して適用された際に送出"
"されます。関連値は型の不整合に関して詳細を述べた文字列です。"

#: ../../library/exceptions.rst:605
msgid ""
"This exception may be raised by user code to indicate that an attempted "
"operation on an object is not supported, and is not meant to be. If an "
"object is meant to support a given operation but has not yet provided an "
"implementation, :exc:`NotImplementedError` is the proper exception to raise."
msgstr ""
"この例外は、そのオブジェクトで実行しようとした操作がサポートされておらず、そ"
"の予定もない場合にユーザーコードから送出されるかもしれません。オブジェクトで"
"その操作をサポートするつもりだが、まだ実装を提供していないのであれば、送出す"
"る適切な例外は :exc:`NotImplementedError` です。"

#: ../../library/exceptions.rst:610
msgid ""
"Passing arguments of the wrong type (e.g. passing a :class:`list` when an :"
"class:`int` is expected) should result in a :exc:`TypeError`, but passing "
"arguments with the wrong value (e.g. a number outside expected boundaries) "
"should result in a :exc:`ValueError`."
msgstr ""
"誤った型の引数が渡された場合は (例えば、:class:`int` が期待されるのに、:"
"class:`list` が渡された) :exc:`TypeError` となるべきです。しかし、誤った値(例"
"えば、期待する範囲外の数)が引数として渡された場合は、 :exc:`ValueError` とな"
"るべきです。"

#: ../../library/exceptions.rst:617
msgid ""
"Raised when a reference is made to a local variable in a function or method, "
"but no value has been bound to that variable.  This is a subclass of :exc:"
"`NameError`."
msgstr ""
"関数やメソッド内のローカルな変数に対して参照を行ったが、その変数には値が代入"
"されていなかった場合に送出されます。 :exc:`NameError` のサブクラスです。"

#: ../../library/exceptions.rst:624
msgid ""
"Raised when a Unicode-related encoding or decoding error occurs.  It is a "
"subclass of :exc:`ValueError`."
msgstr ""
"Unicode に関するエンコードまたはデコードのエラーが発生した際に送出されま"
"す。 :exc:`ValueError` のサブクラスです。"

#: ../../library/exceptions.rst:627
msgid ""
":exc:`UnicodeError` has attributes that describe the encoding or decoding "
"error.  For example, ``err.object[err.start:err.end]`` gives the particular "
"invalid input that the codec failed on."
msgstr ""
":exc:`UnicodeError` はエンコードまたはデコードのエラーの説明を属性として持っ"
"ています。例えば、 ``err.object[err.start:err.end]`` は、無効な入力のうちコー"
"デックが処理に失敗した箇所を表します。"

#: ../../library/exceptions.rst:633
msgid "The name of the encoding that raised the error."
msgstr "エラーを送出したエンコーディングの名前です。"

#: ../../library/exceptions.rst:637
msgid "A string describing the specific codec error."
msgstr "そのコーデックエラーを説明する文字列です。"

#: ../../library/exceptions.rst:641
msgid "The object the codec was attempting to encode or decode."
msgstr "コーデックがエンコードまたはデコードしようとしたオブジェクトです。"

#: ../../library/exceptions.rst:645
msgid "The first index of invalid data in :attr:`object`."
msgstr ":attr:`object` の最初の無効なデータのインデクスです。"

#: ../../library/exceptions.rst:649
msgid "The index after the last invalid data in :attr:`object`."
msgstr ":attr:`object` の最後の無効なデータの次のインデクスです。"

#: ../../library/exceptions.rst:654
msgid ""
"Raised when a Unicode-related error occurs during encoding.  It is a "
"subclass of :exc:`UnicodeError`."
msgstr ""
"Unicode 関連のエラーがエンコード中に発生した際に送出されます。 :exc:"
"`UnicodeError` のサブクラスです。"

#: ../../library/exceptions.rst:660
msgid ""
"Raised when a Unicode-related error occurs during decoding.  It is a "
"subclass of :exc:`UnicodeError`."
msgstr ""
"Unicode 関連のエラーがデコード中に発生した際に送出されます。 :exc:"
"`UnicodeError` のサブクラスです。"

#: ../../library/exceptions.rst:666
msgid ""
"Raised when a Unicode-related error occurs during translating.  It is a "
"subclass of :exc:`UnicodeError`."
msgstr ""
"Unicode 関連のエラーが変換中に発生した際に送出されます。 :exc:`UnicodeError` "
"のサブクラスです。"

#: ../../library/exceptions.rst:672
msgid ""
"Raised when an operation or function receives an argument that has the right "
"type but an inappropriate value, and the situation is not described by a "
"more precise exception such as :exc:`IndexError`."
msgstr ""
"演算子や関数が、正しい型だが適切でない値を持つ引数を受け取ったときや、 :exc:"
"`IndexError` のようなより詳細な例外では記述できない状況で送出されます。"

#: ../../library/exceptions.rst:679
msgid ""
"Raised when the second argument of a division or modulo operation is zero.  "
"The associated value is a string indicating the type of the operands and the "
"operation."
msgstr ""
"除算や剰余演算の第二引数が 0 であった場合に送出されます。関連値は文字列で、そ"
"の演算における被演算子と演算子の型を示します。"

#: ../../library/exceptions.rst:684
msgid ""
"The following exceptions are kept for compatibility with previous versions; "
"starting from Python 3.3, they are aliases of :exc:`OSError`."
msgstr ""
"以下の例外は、過去のバージョンとの後方互換性のために残されています; Python "
"3.3 より、これらは :exc:`OSError` のエイリアスです。"

#: ../../library/exceptions.rst:693
msgid "Only available on Windows."
msgstr "Windows でのみ利用できます。"

#: ../../library/exceptions.rst:697
msgid "OS exceptions"
msgstr "OS 例外"

#: ../../library/exceptions.rst:699
msgid ""
"The following exceptions are subclasses of :exc:`OSError`, they get raised "
"depending on the system error code."
msgstr ""
"以下の例外は :exc:`OSError` のサブクラスで、システムエラーコードに依存して送"
"出されます。"

#: ../../library/exceptions.rst:704
msgid ""
"Raised when an operation would block on an object (e.g. socket) set for non-"
"blocking operation. Corresponds to :c:data:`errno` :py:const:`~errno."
"EAGAIN`, :py:const:`~errno.EALREADY`, :py:const:`~errno.EWOULDBLOCK` and :py:"
"const:`~errno.EINPROGRESS`."
msgstr ""
"ある操作が、ノンブロッキング操作に設定されたオブジェクト (例えばソケット) を"
"ブロックしそうになった場合に送出されます。:c:data:`errno` :py:const:`~errno."
"EAGAIN`, :py:const:`~errno.EALREADY`, :py:const:`~errno.EWOULDBLOCK` および :"
"py:const:`~errno.EINPROGRESS` に対応します。"

#: ../../library/exceptions.rst:709
msgid ""
"In addition to those of :exc:`OSError`, :exc:`BlockingIOError` can have one "
"more attribute:"
msgstr ""
":exc:`BlockingIOError` は、 :exc:`OSError` の属性に加えて一つの属性を持ちま"
"す:"

#: ../../library/exceptions.rst:714
msgid ""
"An integer containing the number of characters written to the stream before "
"it blocked.  This attribute is available when using the buffered I/O classes "
"from the :mod:`io` module."
msgstr ""
"ストリームがブロックされるまでに書き込まれた文字数を含む整数です。この属性"
"は :mod:`io` からのバッファ I/O クラスを使っているときに利用できます。"

#: ../../library/exceptions.rst:720
msgid ""
"Raised when an operation on a child process failed. Corresponds to :c:data:"
"`errno` :py:const:`~errno.ECHILD`."
msgstr ""
"子プロセスの操作が失敗した場合に送出されます。:c:data:`errno` :py:const:"
"`~errno.ECHILD` に対応します。"

#: ../../library/exceptions.rst:725
msgid "A base class for connection-related issues."
msgstr "コネクション関係の問題の基底クラス。"

#: ../../library/exceptions.rst:727
msgid ""
"Subclasses are :exc:`BrokenPipeError`, :exc:`ConnectionAbortedError`, :exc:"
"`ConnectionRefusedError` and :exc:`ConnectionResetError`."
msgstr ""
"サブクラスは :exc:`BrokenPipeError`, :exc:`ConnectionAbortedError`, :exc:"
"`ConnectionRefusedError`, :exc:`ConnectionResetError` です。"

#: ../../library/exceptions.rst:732
msgid ""
"A subclass of :exc:`ConnectionError`, raised when trying to write on a pipe "
"while the other end has been closed, or trying to write on a socket which "
"has been shutdown for writing. Corresponds to :c:data:`errno` :py:const:"
"`~errno.EPIPE` and :py:const:`~errno.ESHUTDOWN`."
msgstr ""
":exc:`ConnectionError` のサブクラスで、もう一方の端が閉じられたパイプに書き込"
"こもうとするか、書き込みのためにシャットダウンされたソケットに書き込こもうと"
"した場合に発生します。 :c:data:`errno`  :py:const:`~errno.EPIPE` と :py:"
"const:`~errno.ESHUTDOWN` に対応します。"

#: ../../library/exceptions.rst:739
msgid ""
"A subclass of :exc:`ConnectionError`, raised when a connection attempt is "
"aborted by the peer. Corresponds to :c:data:`errno` :py:const:`~errno."
"ECONNABORTED`."
msgstr ""
":exc:`ConnectionError` のサブクラスで、接続の試行が通信相手によって中断された"
"場合に発生します。 :c:data:`errno` :py:const:`~errno.ECONNABORTED` に対応しま"
"す。"

#: ../../library/exceptions.rst:745
msgid ""
"A subclass of :exc:`ConnectionError`, raised when a connection attempt is "
"refused by the peer. Corresponds to :c:data:`errno` :py:const:`~errno."
"ECONNREFUSED`."
msgstr ""
":exc:`ConnectionError` のサブクラスで、接続の試行が通信相手によって拒否された"
"場合に発生します。 :c:data:`errno` :py:const:`~errno.ECONNREFUSED` に対応しま"
"す。"

#: ../../library/exceptions.rst:751
msgid ""
"A subclass of :exc:`ConnectionError`, raised when a connection is reset by "
"the peer. Corresponds to :c:data:`errno` :py:const:`~errno.ECONNRESET`."
msgstr ""
":exc:`ConnectionError` のサブクラスで、接続が通信相手によってリセットされた場"
"合に発生します。 :c:data:`errno` :py:const:`~errno.ECONNRESET` に対応します。"

#: ../../library/exceptions.rst:757
msgid ""
"Raised when trying to create a file or directory which already exists. "
"Corresponds to :c:data:`errno` :py:const:`~errno.EEXIST`."
msgstr ""
"すでに存在するファイルやディレクトリを作成しようとした場合に送出されます。:c:"
"data:`errno` :py:const:`~errno.EEXIST` に対応します。"

#: ../../library/exceptions.rst:762
msgid ""
"Raised when a file or directory is requested but doesn't exist. Corresponds "
"to :c:data:`errno` :py:const:`~errno.ENOENT`."
msgstr ""
"要求されたファイルやディレクトリが存在しない場合に送出されます。:c:data:"
"`errno` :py:const:`~errno.ENOENT` に対応します。"

#: ../../library/exceptions.rst:767
msgid ""
"Raised when a system call is interrupted by an incoming signal. Corresponds "
"to :c:data:`errno` :py:const:`~errno.EINTR`."
msgstr ""
"システムコールが入力信号によって中断された場合に送出されます。:c:data:"
"`errno` :py:const:`~errno.EINTR` に対応します。"

#: ../../library/exceptions.rst:770
msgid ""
"Python now retries system calls when a syscall is interrupted by a signal, "
"except if the signal handler raises an exception (see :pep:`475` for the "
"rationale), instead of raising :exc:`InterruptedError`."
msgstr ""
"シグナルハンドラが例外を送出せず、システムコールが信号で中断された場合\n"
"Python は :exc:`InterruptedError` を送出する代わりにシステムコールを再試行す"
"るようになりました (論拠については :pep:`475` を参照してください) 。"

#: ../../library/exceptions.rst:777
msgid ""
"Raised when a file operation (such as :func:`os.remove`) is requested on a "
"directory. Corresponds to :c:data:`errno` :py:const:`~errno.EISDIR`."
msgstr ""
"ディレクトリに (:func:`os.remove` などの) ファイル操作が要求された場合に送出"
"されます。:c:data:`errno` :py:const:`~errno.EISDIR` に対応します。"

#: ../../library/exceptions.rst:783
msgid ""
"Raised when a directory operation (such as :func:`os.listdir`) is requested "
"on something which is not a directory.  On most POSIX platforms, it may also "
"be raised if an operation attempts to open or traverse a non-directory file "
"as if it were a directory. Corresponds to :c:data:`errno` :py:const:`~errno."
"ENOTDIR`."
msgstr ""
"ディレクトリへの操作(たとえば :func:`os.listdir`)をディレクトリ以外に対して要"
"求された場合に送出されます。多くのPOSIXプラットフォームではディレクトリではな"
"いファイルをディレクトリとして開いたり移動するときにも発生する場合がありま"
"す。:c:data:`errno` :py:const:`~errno.ENOTDIR` に対応します。"

#: ../../library/exceptions.rst:791
msgid ""
"Raised when trying to run an operation without the adequate access rights - "
"for example filesystem permissions. Corresponds to :c:data:`errno` :py:const:"
"`~errno.EACCES`, :py:const:`~errno.EPERM`, and :py:const:`~errno."
"ENOTCAPABLE`."
msgstr ""
"十分なアクセス権、例えばファイルシステム権限のない操作が試みられた場合に送出"
"されます。:c:data:`errno` :py:const:`~errno.EACCES`、:py:const:`~errno."
"EPERM` および :py:const:`~errno.ENOTCAPABLE` に対応します。"

#: ../../library/exceptions.rst:796
msgid ""
"WASI's :py:const:`~errno.ENOTCAPABLE` is now mapped to :exc:"
"`PermissionError`."
msgstr ""
"WASIの :py:const:`~errno.ENOTCAPABLE` は :exc:`PermissionError` にマップされ"
"ました。"

#: ../../library/exceptions.rst:802
msgid ""
"Raised when a given process doesn't exist. Corresponds to :c:data:`errno` :"
"py:const:`~errno.ESRCH`."
msgstr ""
"与えられたプロセスが存在しない場合に送出されます。:c:data:`errno` :py:const:"
"`~errno.ESRCH` に対応します。"

#: ../../library/exceptions.rst:807
msgid ""
"Raised when a system function timed out at the system level. Corresponds to :"
"c:data:`errno` :py:const:`~errno.ETIMEDOUT`."
msgstr ""
"システム関数がシステムレベルでタイムアウトした場合に送出されます。:c:data:"
"`errno` :py:const:`~errno.ETIMEDOUT` に対応します。"

#: ../../library/exceptions.rst:810
msgid "All the above :exc:`OSError` subclasses were added."
msgstr "上記のすべての :exc:`OSError` サブクラスが追加されました。"

#: ../../library/exceptions.rst:816
msgid ":pep:`3151` - Reworking the OS and IO exception hierarchy"
msgstr ":pep:`3151` - OS および IO 例外階層の手直し"

#: ../../library/exceptions.rst:822
msgid "Warnings"
msgstr "警告"

#: ../../library/exceptions.rst:824
msgid ""
"The following exceptions are used as warning categories; see the :ref:"
"`warning-categories` documentation for more details."
msgstr ""
"次の例外は警告カテゴリとして使われます。詳細については :ref:`warning-"
"categories` のドキュメントを参照してください。"

#: ../../library/exceptions.rst:829
msgid "Base class for warning categories."
msgstr "警告カテゴリの基底クラスです。"

#: ../../library/exceptions.rst:834
msgid "Base class for warnings generated by user code."
msgstr "ユーザコードによって生成される警告の基底クラスです。"

#: ../../library/exceptions.rst:839
msgid ""
"Base class for warnings about deprecated features when those warnings are "
"intended for other Python developers."
msgstr ""
"他の Python 開発者へ向けて警告を発するときの、廃止予定の機能についての警告の"
"基底クラスです。"

#: ../../library/exceptions.rst:842
msgid ""
"Ignored by the default warning filters, except in the ``__main__`` module (:"
"pep:`565`). Enabling the :ref:`Python Development Mode <devmode>` shows this "
"warning."
msgstr ""
"``__main__`` モジュールを除いて(:pep:`565`)、デフォルトの警告フィルターで無効"
"化されています。:ref:`Python Development Mode <devmode>` を有効にするとこの警"
"告が表示されます。"

#: ../../library/exceptions.rst:846 ../../library/exceptions.rst:862
msgid "The deprecation policy is described in :pep:`387`."
msgstr ""

#: ../../library/exceptions.rst:851
msgid ""
"Base class for warnings about features which are obsolete and expected to be "
"deprecated in the future, but are not deprecated at the moment."
msgstr ""
"古くなって将来的に廃止される予定だが、今のところは廃止されていない機能につい"
"ての警告の基底クラスです。"

#: ../../library/exceptions.rst:855
msgid ""
"This class is rarely used as emitting a warning about a possible upcoming "
"deprecation is unusual, and :exc:`DeprecationWarning` is preferred for "
"already active deprecations."
msgstr ""
"近々起こる可能性のある機能廃止について警告を発することはまれなので、このクラ"
"スはめったに使われず、既に決まっている廃止については :exc:"
"`DeprecationWarning` が望ましいです。"

#: ../../library/exceptions.rst:859 ../../library/exceptions.rst:885
#: ../../library/exceptions.rst:912
msgid ""
"Ignored by the default warning filters. Enabling the :ref:`Python "
"Development Mode <devmode>` shows this warning."
msgstr ""
"デフォルトの警告フィルターで無効化されています。:ref:`Python Development "
"Mode <devmode>` を有効にするとこの警告が表示されます。"

#: ../../library/exceptions.rst:867
msgid "Base class for warnings about dubious syntax."
msgstr "曖昧な構文に対する警告の基底クラスです。"

#: ../../library/exceptions.rst:872
msgid "Base class for warnings about dubious runtime behavior."
msgstr "あいまいなランタイム挙動に対する警告の基底クラスです。"

#: ../../library/exceptions.rst:877
msgid ""
"Base class for warnings about deprecated features when those warnings are "
"intended for end users of applications that are written in Python."
msgstr ""
"Python で書かれたアプリケーションのエンドユーザーへ向けて警告を発するときの、"
"廃止予定の機能についての警告の基底クラスです。"

#: ../../library/exceptions.rst:883
msgid "Base class for warnings about probable mistakes in module imports."
msgstr "モジュールインポートの誤りと思われるものに対する警告の基底クラスです。"

#: ../../library/exceptions.rst:891
msgid "Base class for warnings related to Unicode."
msgstr "Unicode に関連した警告の基底クラスです。"

#: ../../library/exceptions.rst:896
msgid "Base class for warnings related to encodings."
msgstr "エンコーディングに関連した警告の基底クラスです。"

#: ../../library/exceptions.rst:898
msgid "See :ref:`io-encoding-warning` for details."
msgstr "詳細は :ref:`io-encoding-warning` を参照してください。"

#: ../../library/exceptions.rst:905
msgid ""
"Base class for warnings related to :class:`bytes` and :class:`bytearray`."
msgstr ":class:`bytes` や :class:`bytearray` に関連した警告の基底クラスです。"

#: ../../library/exceptions.rst:910
msgid "Base class for warnings related to resource usage."
msgstr "リソースの使用に関連した警告の基底クラスです。"

#: ../../library/exceptions.rst:921
msgid "Exception groups"
msgstr "例外グループ"

#: ../../library/exceptions.rst:923
msgid ""
"The following are used when it is necessary to raise multiple unrelated "
"exceptions. They are part of the exception hierarchy so they can be handled "
"with :keyword:`except` like all other exceptions. In addition, they are "
"recognised by :keyword:`except*<except_star>`, which matches their subgroups "
"based on the types of the contained exceptions."
msgstr ""
"以下は関係がない複数の例外を送出する必要があるときに使用します。例外グループ"
"は例外の階層構造の一部のため、他の例外と同様 :keyword:`except` で処理できま"
"す。また、:keyword:`except*<except_star>` によって判別でき、例外グループに含"
"まれている例外の型に基づいてサブグループにマッチします。"

#: ../../library/exceptions.rst:932
msgid ""
"Both of these exception types wrap the exceptions in the sequence ``excs``. "
"The ``msg`` parameter must be a string. The difference between the two "
"classes is that :exc:`BaseExceptionGroup` extends :exc:`BaseException` and "
"it can wrap any exception, while :exc:`ExceptionGroup` extends :exc:"
"`Exception` and it can only wrap subclasses of :exc:`Exception`. This design "
"is so that ``except Exception`` catches an :exc:`ExceptionGroup` but not :"
"exc:`BaseExceptionGroup`."
msgstr ""
"この2つの例外型は一連の例外 ``excs`` を包含します。``msg`` 引数は文字列の必要"
"があります。2つのクラスの異なる点は、:exc:`BaseException` は :exc:"
"`BaseExceptionGroup` を拡張して任意の例外を含められますが、:exc:"
"`ExceptionGroup` は :exc:`Exception` を拡張して :exc:`Exception` のサブクラス"
"のみを含められます。この設計により ``except Exception`` は :exc:"
"`ExceptionGroup` をキャッチしますが、:exc:`BaseExceptionGroup` はキャッチしま"
"せん。"

#: ../../library/exceptions.rst:940
msgid ""
"The :exc:`BaseExceptionGroup` constructor returns an :exc:`ExceptionGroup` "
"rather than a :exc:`BaseExceptionGroup` if all contained exceptions are :exc:"
"`Exception` instances, so it can be used to make the selection automatic. "
"The :exc:`ExceptionGroup` constructor, on the other hand, raises a :exc:"
"`TypeError` if any contained exception is not an :exc:`Exception` subclass."
msgstr ""
":exc:`BaseExceptionGroup` のコンストラクターは含まれる例外がすべて :exc:"
"`Exception` の場合は :exc:`BaseExceptionGroup` ではなく :exc:"
"`ExceptionGroup` を返すように自動的に選択されます。一方 :exc:"
"`ExceptionGroup` コンストラクタは、:exc:`Exception` サブクラス以外の例外を含"
"む場合は :exc:`TypeError` を送出します。"

#: ../../library/exceptions.rst:949
msgid "The ``msg`` argument to the constructor. This is a read-only attribute."
msgstr "コンストラクタの ``msg`` 引数。この属性は読み込み専用です。"

#: ../../library/exceptions.rst:953
msgid ""
"A tuple of the exceptions in the ``excs`` sequence given to the constructor. "
"This is a read-only attribute."
msgstr ""
"コンストラクタに渡された一連の ``excs`` に含まれる例外のタプルです。この属性"
"は読み込み専用です。"

#: ../../library/exceptions.rst:958
msgid ""
"Returns an exception group that contains only the exceptions from the "
"current group that match *condition*, or ``None`` if the result is empty."
msgstr ""
"現在のグループで *条件* にマッチする礼儀のみを含む例外グループを返します。結"
"果が空の場合は ``None`` を返します。"

#: ../../library/exceptions.rst:961
msgid ""
"The condition can be an exception type or tuple of exception types, in which "
"case each exception is checked for a match using the same check that is used "
"in an ``except`` clause.  The condition can also be a callable (other than a "
"type object) that accepts an exception as its single argument and returns "
"true for the exceptions that should be in the subgroup."
msgstr ""

#: ../../library/exceptions.rst:967
msgid ""
"The nesting structure of the current exception is preserved in the result, "
"as are the values of its :attr:`message`, :attr:`~BaseException."
"__traceback__`, :attr:`~BaseException.__cause__`, :attr:`~BaseException."
"__context__` and :attr:`~BaseException.__notes__` fields. Empty nested "
"groups are omitted from the result."
msgstr ""

#: ../../library/exceptions.rst:974
msgid ""
"The condition is checked for all exceptions in the nested exception group, "
"including the top-level and any nested exception groups. If the condition is "
"true for such an exception group, it is included in the result in full."
msgstr ""

#: ../../library/exceptions.rst:978
msgid "``condition`` can be any callable which is not a type object."
msgstr ""

#: ../../library/exceptions.rst:983
msgid ""
"Like :meth:`subgroup`, but returns the pair ``(match, rest)`` where "
"``match`` is ``subgroup(condition)`` and ``rest`` is the remaining non-"
"matching part."
msgstr ""
":meth:`subgroup` と似てますが ``(match, rest)`` のペアを返します。``match`` "
"は ``subgroup(condition)`` で ``rest`` は残りのマッチしない部分です。"

#: ../../library/exceptions.rst:989
msgid ""
"Returns an exception group with the same :attr:`message`, but which wraps "
"the exceptions in ``excs``."
msgstr ""
"同じ :attr:`message` の例外グループを返しますが、``excs`` の例外を含んでいま"
"す。"

#: ../../library/exceptions.rst:992
msgid ""
"This method is used by :meth:`subgroup` and :meth:`split`, which are used in "
"various contexts to break up an exception group. A subclass needs to "
"override it in order to make :meth:`subgroup` and :meth:`split` return "
"instances of the subclass rather than :exc:`ExceptionGroup`."
msgstr ""

#: ../../library/exceptions.rst:998
msgid ""
":meth:`subgroup` and :meth:`split` copy the :attr:`~BaseException."
"__traceback__`, :attr:`~BaseException.__cause__`, :attr:`~BaseException."
"__context__` and :attr:`~BaseException.__notes__` fields from the original "
"exception group to the one returned by :meth:`derive`, so these fields do "
"not need to be updated by :meth:`derive`."
msgstr ""
":meth:`subgroup` と :meth:`split` は :attr:`~BaseException.__traceback__`、:"
"attr:`~BaseException.__cause__`、:attr:`~BaseException.__context__` と :attr:"
"`~BaseException.__notes__` フィールドを元の例外グループから :meth:`derive` が"
"返す例外グループにコピーするため、:meth:`derive` ではこれらのフィールドを更新"
"する必要がありません。"

#: ../../library/exceptions.rst:1005
msgid ""
">>> class MyGroup(ExceptionGroup):\n"
"...     def derive(self, excs):\n"
"...         return MyGroup(self.message, excs)\n"
"...\n"
">>> e = MyGroup(\"eg\", [ValueError(1), TypeError(2)])\n"
">>> e.add_note(\"a note\")\n"
">>> e.__context__ = Exception(\"context\")\n"
">>> e.__cause__ = Exception(\"cause\")\n"
">>> try:\n"
"...    raise e\n"
"... except Exception as e:\n"
"...    exc = e\n"
"...\n"
">>> match, rest = exc.split(ValueError)\n"
">>> exc, exc.__context__, exc.__cause__, exc.__notes__\n"
"(MyGroup('eg', [ValueError(1), TypeError(2)]), Exception('context'), "
"Exception('cause'), ['a note'])\n"
">>> match, match.__context__, match.__cause__, match.__notes__\n"
"(MyGroup('eg', [ValueError(1)]), Exception('context'), Exception('cause'), "
"['a note'])\n"
">>> rest, rest.__context__, rest.__cause__, rest.__notes__\n"
"(MyGroup('eg', [TypeError(2)]), Exception('context'), Exception('cause'), "
"['a note'])\n"
">>> exc.__traceback__ is match.__traceback__ is rest.__traceback__\n"
"True"
msgstr ""

#: ../../library/exceptions.rst:1031
msgid ""
"Note that :exc:`BaseExceptionGroup` defines :meth:`~object.__new__`, so "
"subclasses that need a different constructor signature need to override that "
"rather than :meth:`~object.__init__`. For example, the following defines an "
"exception group subclass which accepts an exit_code and and constructs the "
"group's message from it. ::"
msgstr ""

#: ../../library/exceptions.rst:1037
msgid ""
"class Errors(ExceptionGroup):\n"
"   def __new__(cls, errors, exit_code):\n"
"      self = super().__new__(Errors, f\"exit code: {exit_code}\", errors)\n"
"      self.exit_code = exit_code\n"
"      return self\n"
"\n"
"   def derive(self, excs):\n"
"      return Errors(excs, self.exit_code)"
msgstr ""

#: ../../library/exceptions.rst:1046
msgid ""
"Like :exc:`ExceptionGroup`, any subclass of :exc:`BaseExceptionGroup` which "
"is also a subclass of :exc:`Exception` can only wrap instances of :exc:"
"`Exception`."
msgstr ""

#: ../../library/exceptions.rst:1054
msgid "Exception hierarchy"
msgstr "例外のクラス階層"

#: ../../library/exceptions.rst:1056
msgid "The class hierarchy for built-in exceptions is:"
msgstr "組み込み例外のクラス階層は以下のとおりです:"

#: ../../library/exceptions.rst:1058
msgid ""
"BaseException\n"
" ├── BaseExceptionGroup\n"
" ├── GeneratorExit\n"
" ├── KeyboardInterrupt\n"
" ├── SystemExit\n"
" └── Exception\n"
"      ├── ArithmeticError\n"
"      │    ├── FloatingPointError\n"
"      │    ├── OverflowError\n"
"      │    └── ZeroDivisionError\n"
"      ├── AssertionError\n"
"      ├── AttributeError\n"
"      ├── BufferError\n"
"      ├── EOFError\n"
"      ├── ExceptionGroup [BaseExceptionGroup]\n"
"      ├── ImportError\n"
"      │    └── ModuleNotFoundError\n"
"      ├── LookupError\n"
"      │    ├── IndexError\n"
"      │    └── KeyError\n"
"      ├── MemoryError\n"
"      ├── NameError\n"
"      │    └── UnboundLocalError\n"
"      ├── OSError\n"
"      │    ├── BlockingIOError\n"
"      │    ├── ChildProcessError\n"
"      │    ├── ConnectionError\n"
"      │    │    ├── BrokenPipeError\n"
"      │    │    ├── ConnectionAbortedError\n"
"      │    │    ├── ConnectionRefusedError\n"
"      │    │    └── ConnectionResetError\n"
"      │    ├── FileExistsError\n"
"      │    ├── FileNotFoundError\n"
"      │    ├── InterruptedError\n"
"      │    ├── IsADirectoryError\n"
"      │    ├── NotADirectoryError\n"
"      │    ├── PermissionError\n"
"      │    ├── ProcessLookupError\n"
"      │    └── TimeoutError\n"
"      ├── ReferenceError\n"
"      ├── RuntimeError\n"
"      │    ├── NotImplementedError\n"
"      │    ├── PythonFinalizationError\n"
"      │    └── RecursionError\n"
"      ├── StopAsyncIteration\n"
"      ├── StopIteration\n"
"      ├── SyntaxError\n"
"      │    └── IndentationError\n"
"      │         └── TabError\n"
"      ├── SystemError\n"
"      ├── TypeError\n"
"      ├── ValueError\n"
"      │    └── UnicodeError\n"
"      │         ├── UnicodeDecodeError\n"
"      │         ├── UnicodeEncodeError\n"
"      │         └── UnicodeTranslateError\n"
"      └── Warning\n"
"           ├── BytesWarning\n"
"           ├── DeprecationWarning\n"
"           ├── EncodingWarning\n"
"           ├── FutureWarning\n"
"           ├── ImportWarning\n"
"           ├── PendingDeprecationWarning\n"
"           ├── ResourceWarning\n"
"           ├── RuntimeWarning\n"
"           ├── SyntaxWarning\n"
"           ├── UnicodeWarning\n"
"           └── UserWarning\n"
msgstr ""

#: ../../library/exceptions.rst:6 ../../library/exceptions.rst:17
#: ../../library/exceptions.rst:196
msgid "statement"
msgstr "statement"

#: ../../library/exceptions.rst:6
msgid "try"
msgstr "try"

#: ../../library/exceptions.rst:6
msgid "except"
msgstr "except"

#: ../../library/exceptions.rst:17
msgid "raise"
msgstr "raise"

#: ../../library/exceptions.rst:41
msgid "exception"
msgstr "例外"

#: ../../library/exceptions.rst:41
msgid "chaining"
msgstr "連鎖"

#: ../../library/exceptions.rst:41
msgid "__cause__ (exception attribute)"
msgstr "__cause__ (exception の属性)"

#: ../../library/exceptions.rst:41
msgid "__context__ (exception attribute)"
msgstr "__context__ (exception の属性)"

#: ../../library/exceptions.rst:41
msgid "__suppress_context__ (exception attribute)"
msgstr "__suppress_context__ (exception の属性)"

#: ../../library/exceptions.rst:196
msgid "assert"
msgstr "assert"

#: ../../library/exceptions.rst:345
msgid "module"
msgstr "module"

#: ../../library/exceptions.rst:345
msgid "errno"
msgstr "errno"
